2017-07-09 00:48:11 [scrapy] INFO: Scrapy 1.0.3 started (bot: site_app_scraper)
2017-07-09 00:48:11 [scrapy] INFO: Optional features available: ssl, http11, boto
2017-07-09 00:48:11 [scrapy] INFO: Overridden settings: {'NEWSPIDER_MODULE': 'site_app_scraper.spiders', 'SPIDER_MODULES': ['site_app_scraper.spiders'], 'LOG_FILE': 'logs/default/news_spider/6ccaed98645911e7a015e4f89c8c903d.log', 'BOT_NAME': 'site_app_scraper'}
2017-07-09 00:48:11 [scrapy] INFO: Enabled extensions: CloseSpider, TelnetConsole, LogStats, CoreStats, SpiderState
2017-07-09 00:48:11 [boto] DEBUG: Retrieving credentials from metadata server.
2017-07-09 00:48:12 [boto] ERROR: Caught exception reading instance data
Traceback (most recent call last):
  File "/usr/lib/python2.7/dist-packages/boto/utils.py", line 210, in retry_url
    r = opener.open(req, timeout=timeout)
  File "/usr/lib/python2.7/urllib2.py", line 429, in open
    response = self._open(req, data)
  File "/usr/lib/python2.7/urllib2.py", line 447, in _open
    '_open', req)
  File "/usr/lib/python2.7/urllib2.py", line 407, in _call_chain
    result = func(*args)
  File "/usr/lib/python2.7/urllib2.py", line 1228, in http_open
    return self.do_open(httplib.HTTPConnection, req)
  File "/usr/lib/python2.7/urllib2.py", line 1198, in do_open
    raise URLError(err)
URLError: <urlopen error timed out>
2017-07-09 00:48:12 [boto] ERROR: Unable to read instance data, giving up
2017-07-09 00:48:12 [scrapy] INFO: Enabled downloader middlewares: HttpAuthMiddleware, DownloadTimeoutMiddleware, UserAgentMiddleware, RetryMiddleware, DefaultHeadersMiddleware, MetaRefreshMiddleware, HttpCompressionMiddleware, RedirectMiddleware, CookiesMiddleware, ChunkedTransferMiddleware, DownloaderStats
2017-07-09 00:48:12 [scrapy] INFO: Enabled spider middlewares: HttpErrorMiddleware, OffsiteMiddleware, RefererMiddleware, UrlLengthMiddleware, DepthMiddleware
2017-07-09 00:48:12 [scrapy] INFO: Enabled item pipelines: SiteAppScraperPipeline
2017-07-09 00:48:12 [scrapy] INFO: Spider opened
2017-07-09 00:48:12 [scrapy] INFO: Crawled 0 pages (at 0 pages/min), scraped 0 items (at 0 items/min)
2017-07-09 00:48:12 [scrapy] DEBUG: Telnet console listening on 127.0.0.1:6023
2017-07-09 00:48:13 [scrapy] DEBUG: Redirecting (301) to <GET http://quotes.wsj.com/company-list> from <GET http://quotes.wsj.com/>
2017-07-09 00:48:14 [scrapy] DEBUG: Crawled (200) <GET http://quotes.wsj.com/company-list> (referer: None)
2017-07-09 00:48:14 [urllib3.connectionpool] DEBUG: Starting new HTTP connection (1): localhost
2017-07-09 00:48:14 [scrapy] ERROR: Spider error processing <GET http://quotes.wsj.com/company-list> (referer: None)
Traceback (most recent call last):
  File "/usr/lib/python2.7/dist-packages/scrapy/utils/defer.py", line 102, in iter_errback
    yield next(it)
  File "/usr/lib/python2.7/dist-packages/scrapy/spidermiddlewares/offsite.py", line 28, in process_spider_output
    for x in result:
  File "/usr/lib/python2.7/dist-packages/scrapy/spidermiddlewares/referer.py", line 22, in <genexpr>
    return (_set_referer(r) for r in result or ())
  File "/usr/lib/python2.7/dist-packages/scrapy/spidermiddlewares/urllength.py", line 37, in <genexpr>
    return (r for r in result or () if _filter(r))
  File "/usr/lib/python2.7/dist-packages/scrapy/spidermiddlewares/depth.py", line 54, in <genexpr>
    return (r for r in result or () if _filter(r))
  File "site_app_scraper/spiders/news.py", line 41, in parse
    request = requests.get("http://localhost:8000/get_companies_codes")
  File "/usr/local/lib/python2.7/dist-packages/requests/api.py", line 72, in get
    return request('get', url, params=params, **kwargs)
  File "/usr/local/lib/python2.7/dist-packages/requests/api.py", line 58, in request
    return session.request(method=method, url=url, **kwargs)
  File "/usr/local/lib/python2.7/dist-packages/requests/sessions.py", line 513, in request
    resp = self.send(prep, **send_kwargs)
  File "/usr/local/lib/python2.7/dist-packages/requests/sessions.py", line 623, in send
    r = adapter.send(request, **kwargs)
  File "/usr/local/lib/python2.7/dist-packages/requests/adapters.py", line 504, in send
    raise ConnectionError(e, request=request)
ConnectionError: HTTPConnectionPool(host='localhost', port=8000): Max retries exceeded with url: /get_companies_codes (Caused by NewConnectionError('<urllib3.connection.HTTPConnection object at 0x7f1a95f8ba10>: Failed to establish a new connection: [Errno 111] Connection refused',))
2017-07-09 00:48:14 [scrapy] INFO: Closing spider (finished)
2017-07-09 00:48:14 [scrapy] INFO: Dumping Scrapy stats:
{'downloader/request_bytes': 694,
 'downloader/request_count': 2,
 'downloader/request_method_count/GET': 2,
 'downloader/response_bytes': 15538,
 'downloader/response_count': 2,
 'downloader/response_status_count/200': 1,
 'downloader/response_status_count/301': 1,
 'finish_reason': 'finished',
 'finish_time': datetime.datetime(2017, 7, 9, 3, 48, 14, 848557),
 'log_count/DEBUG': 5,
 'log_count/ERROR': 3,
 'log_count/INFO': 7,
 'response_received_count': 1,
 'scheduler/dequeued': 2,
 'scheduler/dequeued/memory': 2,
 'scheduler/enqueued': 2,
 'scheduler/enqueued/memory': 2,
 'spider_exceptions/ConnectionError': 1,
 'start_time': datetime.datetime(2017, 7, 9, 3, 48, 12, 968895)}
2017-07-09 00:48:14 [scrapy] INFO: Spider closed (finished)
